Workbook
Name CategoryList: Setup!$B$5:$B$29
Name EmployeeList: Setup!$C$5:$C$29
Name FlagPercent: 'Project Tracker'!$G$2

Sheet Project Tracker
B2: Project Task Tracker | F2: Percent over/under to highlighted numbers | G2: 0
B4: Task | C4: Category | D4: Assigned to | E4: Actual start | F4: Actual finish | G4: Actual work (in hours) | H4: Actual duration (in days) | I4: Notes (credit also applies to:)
B5: IGameHandler - structure diagram | C5: Document | D5: Alan Bach | E5: 45595 | F5: 45595 | G5: 1 | H5: =IF(COUNTA('Project Tracker'!$E5,'Project Tracker'!$F5)<>2,"",DAYS360('Project Tracker'!$E5,'Project Tracker'!$F5,FALSE)) -> 0
B6: Start Game - use case description | C6: Document | D6: Elizabeth Akinpelu | E6: 45596 | F6: 45596 | G6: 1 | H6: =IF(COUNTA('Project Tracker'!$E6,'Project Tracker'!$F6)<>2,"",DAYS360('Project Tracker'!$E6,'Project Tracker'!$F6,FALSE)) -> 0 | I6: Alan Bach, Anmoldeep Gill, Ethan Braum
B7: Game Handler - structure diagram | C7: Document | D7: Alan Bach | E7: 45595 | F7: 45595 | G7: 1 | H7: =IF(COUNTA('Project Tracker'!$E7,'Project Tracker'!$F7)<>2,"",DAYS360('Project Tracker'!$E7,'Project Tracker'!$F7,FALSE)) -> 0
B8: Choose A Side - use case description | C8: Document | D8: Victoria Piquer | E8: 45595 | F8: 45596 | G8: 1 | H8: =IF(COUNTA('Project Tracker'!$E8,'Project Tracker'!$F8)<>2,"",DAYS360('Project Tracker'!$E8,'Project Tracker'!$F8,FALSE)) -> 0 | I8: Alan Bach
B9: Resign Game - use case description | C9: Document | D9: Victoria Piquer | E9: 45595 | F9: 45595 | G9: 1 | H9: =IF(COUNTA('Project Tracker'!$E9,'Project Tracker'!$F9)<>2,"",DAYS360('Project Tracker'!$E9,'Project Tracker'!$F9,FALSE)) -> 0 | I9: Alan Bach
B10: Place A Piece - use case description | C10: Document | D10: Anmoldeep Gill | E10: 45595 | F10: 45595 | G10: 1 | H10: =IF(COUNTA('Project Tracker'!$E10,'Project Tracker'!$F10)<>2,"",DAYS360('Project Tracker'!$E10,'Project Tracker'!$F10,FALSE)) -> 0 | I10: Alan Bach, Ethan Barum
B11: GameBoard - structure diagram | C11: Document | D11: Gabriel Moises | E11: 45595 | F11: 45595 | G11: 1 | H11: =IF(COUNTA('Project Tracker'!$E11,'Project Tracker'!$F11)<>2,"",DAYS360('Project Tracker'!$E11,'Project Tracker'!$F11,FALSE)) -> 0 | I11: Alan Bach
B12: Tic Tac Toe - use case description | C12: Document | D12: Tanisha Mattapalli | E12: 45598 | F12: 45599 | G12: 1 | H12: =IF(COUNTA('Project Tracker'!$E12,'Project Tracker'!$F12)<>2,"",DAYS360('Project Tracker'!$E12,'Project Tracker'!$F12,FALSE)) -> 1 | I12: Richard Nguyen
B13: Player Profile - use case description | C13: Document | D13: Michelle Yoon | E13: 45599 | F13: 45599 | G13: 1 | H13: =IF(COUNTA('Project Tracker'!$E13,'Project Tracker'!$F13)<>2,"",DAYS360('Project Tracker'!$E13,'Project Tracker'!$F13,FALSE)) -> 0 | I13: Richard Nguyen
B14: Checkers Piece - structure diagram | C14: Document | D14: Orest Sinani | E14: 45599 | F14: 45599 | G14: 1 | H14: =IF(COUNTA('Project Tracker'!$E14,'Project Tracker'!$F14)<>2,"",DAYS360('Project Tracker'!$E14,'Project Tracker'!$F14,FALSE)) -> 0 | I14: Alan Bach
B15: Frontend - structure diagram | C15: Document | D15: Richard Nguyen | E15: 45599 | F15: 45599 | G15: 1 | H15: =IF(COUNTA('Project Tracker'!$E15,'Project Tracker'!$F15)<>2,"",DAYS360('Project Tracker'!$E15,'Project Tracker'!$F15,FALSE)) -> 0
B16: Frontend - use case diagram | C16: Document | D16: Richard Nguyen | E16: 45599 | F16: 45599 | G16: 1 | H16: =IF(COUNTA('Project Tracker'!$E16,'Project Tracker'!$F16)<>2,"",DAYS360('Project Tracker'!$E16,'Project Tracker'!$F16,FALSE)) -> 0 | I16: Michelle Yoon, Amir Khan
B17: Connect 4 - use case description | C17: Document | D17: Richard Nguyen | E17: 45599 | F17: 45599 | G17: 1 | H17: =IF(COUNTA('Project Tracker'!$E17,'Project Tracker'!$F17)<>2,"",DAYS360('Project Tracker'!$E17,'Project Tracker'!$F17,FALSE)) -> 0
B18: Tic Tac Toe Piece - structure diagram | C18: Document | D18: Orest Sinani | E18: 45599 | F18: 45599 | G18: 1 | H18: =IF(COUNTA('Project Tracker'!$E18,'Project Tracker'!$F18)<>2,"",DAYS360('Project Tracker'!$E18,'Project Tracker'!$F18,FALSE)) -> 0 | I18: Alan Bach
B19: Connect 4 Piece - structure diagram | C19: Document | D19: Orest Sinani | E19: 45599 | F19: 45599 | G19: 1 | H19: =IF(COUNTA('Project Tracker'!$E19,'Project Tracker'!$F19)<>2,"",DAYS360('Project Tracker'!$E19,'Project Tracker'!$F19,FALSE)) -> 0 | I19: Gabriel Moises, Alan Bach
B20: Checkers Check for Capture - use case description | C20: Document | D20: Victoria Piquer | E20: 45598 | F20: 45599 | G20: 1 | H20: =IF(COUNTA('Project Tracker'!$E20,'Project Tracker'!$F20)<>2,"",DAYS360('Project Tracker'!$E20,'Project Tracker'!$F20,FALSE)) -> 1 | I20: Alan Bach
B21: Check Game End - sequence diagram | C21: Document | D21: Mostafa Abdelazim | E21: 45596 | F21: 45599 | G21: 1 | H21: =IF(COUNTA('Project Tracker'!$E21,'Project Tracker'!$F21)<>2,"",DAYS360('Project Tracker'!$E21,'Project Tracker'!$F21,FALSE)) -> 3
B22: Backend - use case diagram | C22: Document | D22: Lisa Tatarnikov | E22: 45596 | F22: 45599 | G22: 1 | H22: =IF(COUNTA('Project Tracker'!$E22,'Project Tracker'!$F22)<>2,"",DAYS360('Project Tracker'!$E22,'Project Tracker'!$F22,FALSE)) -> 3 | I22: Alan Bach
B23: Aftermath - use case description | C23: Document | D23: Amir Khan | E23: 45597 | F23: 45597 | G23: 1 | H23: =IF(COUNTA('Project Tracker'!$E23,'Project Tracker'!$F23)<>2,"",DAYS360('Project Tracker'!$E23,'Project Tracker'!$F23,FALSE)) -> 0 | I23: Richard Nguyen
B24: Checkers - use case description | C24: Document | D24: Sharon Wong | E24: 45595 | F24: 45599 | G24: 1 | H24: =IF(COUNTA('Project Tracker'!$E24,'Project Tracker'!$F24)<>2,"",DAYS360('Project Tracker'!$E24,'Project Tracker'!$F24,FALSE)) -> 3 | I24: Richard Nguyen
B25: Leaderboard - use case description | C25: Document | D25: Alan Bach | E25: 45594 | F25: 45599 | G25: 2 | H25: =IF(COUNTA('Project Tracker'!$E25,'Project Tracker'!$F25)<>2,"",DAYS360('Project Tracker'!$E25,'Project Tracker'!$F25,FALSE)) -> 4 | I25: Rishabh Agarwal, Richard Nguyen, Mohammad Moustaqim
B26: Login/Sign Out - use case diagram | C26: Document | D26: Natesh Oad | E26: 45594 | F26: 45598 | G26: 1 | H26: =IF(COUNTA('Project Tracker'!$E26,'Project Tracker'!$F26)<>2,"",DAYS360('Project Tracker'!$E26,'Project Tracker'!$F26,FALSE)) -> 3 | I26: Richard Nguyen
B27: Update Player Timer - use case description | C27: Document | D27: Mostafa Abdelazim | E27: 45597 | F27: 45598 | G27: 1 | H27: =IF(COUNTA('Project Tracker'!$E27,'Project Tracker'!$F27)<>2,"",DAYS360('Project Tracker'!$E27,'Project Tracker'!$F27,FALSE)) -> 1 | I27: Alan Bach, Gabriel Moises
B28: Check Game End - use case description | C28: Document | D28: Anmoldeep Gill | E28: 45596 | F28: 45598 | G28: 1 | H28: =IF(COUNTA('Project Tracker'!$E28,'Project Tracker'!$F28)<>2,"",DAYS360('Project Tracker'!$E28,'Project Tracker'!$F28,FALSE)) -> 2 | I28: Alan Bach
B29: Connect 4 Handler - structure diagram | C29: Document | D29: Alan Bach | E29: 45596 | F29: 45597 | G29: 1 | H29: =IF(COUNTA('Project Tracker'!$E29,'Project Tracker'!$F29)<>2,"",DAYS360('Project Tracker'!$E29,'Project Tracker'!$F29,FALSE)) -> 1
B30: Validate Move - use case description | C30: Document | D30: Anmoldeep Gill | E30: 45596 | F30: 45598 | G30: 1 | H30: =IF(COUNTA('Project Tracker'!$E30,'Project Tracker'!$F30)<>2,"",DAYS360('Project Tracker'!$E30,'Project Tracker'!$F30,FALSE)) -> 2 | I30: Alan Bach
B31: Tic Tac Toe Handler - structure diagram | C31: Document | D31: Alan Bach | E31: 45596 | F31: 45597 | G31: 1 | H31: =IF(COUNTA('Project Tracker'!$E31,'Project Tracker'!$F31)<>2,"",DAYS360('Project Tracker'!$E31,'Project Tracker'!$F31,FALSE)) -> 1
B32: Connect 4 Queue - use case diagram | C32: Document | D32: Mohammad Moustaqim | E32: 45597 | F32: 45599 | G32: 4 | H32: =IF(COUNTA('Project Tracker'!$E32,'Project Tracker'!$F32)<>2,"",DAYS360('Project Tracker'!$E32,'Project Tracker'!$F32,FALSE)) -> 2
B33: Checkers Handler - structure diagram | C33: Document | D33: Alan Bach | E33: 45596 | F33: 45597 | G33: 1 | H33: =IF(COUNTA('Project Tracker'!$E33,'Project Tracker'!$F33)<>2,"",DAYS360('Project Tracker'!$E33,'Project Tracker'!$F33,FALSE)) -> 1
B34: Game Piece - structure diagram | C34: Document | D34: Kyle Salazar | E34: 45596 | F34: 45597 | G34: 1 | H34: =IF(COUNTA('Project Tracker'!$E34,'Project Tracker'!$F34)<>2,"",DAYS360('Project Tracker'!$E34,'Project Tracker'!$F34,FALSE)) -> 1
H35: =IF(COUNTA('Project Tracker'!$E35,'Project Tracker'!$F35)<>2,"",DAYS360('Project Tracker'!$E35,'Project Tracker'!$F35,FALSE))
H36: =IF(COUNTA('Project Tracker'!$E36,'Project Tracker'!$F36)<>2,"",DAYS360('Project Tracker'!$E36,'Project Tracker'!$F36,FALSE))
H37: =IF(COUNTA('Project Tracker'!$E37,'Project Tracker'!$F37)<>2,"",DAYS360('Project Tracker'!$E37,'Project Tracker'!$F37,FALSE))
H38: =IF(COUNTA('Project Tracker'!$E38,'Project Tracker'!$F38)<>2,"",DAYS360('Project Tracker'!$E38,'Project Tracker'!$F38,FALSE))
H39: =IF(COUNTA('Project Tracker'!$E39,'Project Tracker'!$F39)<>2,"",DAYS360('Project Tracker'!$E39,'Project Tracker'!$F39,FALSE))
H40: =IF(COUNTA('Project Tracker'!$E40,'Project Tracker'!$F40)<>2,"",DAYS360('Project Tracker'!$E40,'Project Tracker'!$F40,FALSE))
H41: =IF(COUNTA('Project Tracker'!$E41,'Project Tracker'!$F41)<>2,"",DAYS360('Project Tracker'!$E41,'Project Tracker'!$F41,FALSE))
H42: =IF(COUNTA('Project Tracker'!$E42,'Project Tracker'!$F42)<>2,"",DAYS360('Project Tracker'!$E42,'Project Tracker'!$F42,FALSE))
...

Sheet Meeting Records
A1: Meeting Purpose | B1: Team Involved | C1: Meeting Date | D1: Meeting Duration (hours)
A2: Initial Team Meeting | B2: All Members | C2: 45593 | D2: 0.041666667
A3: Initial Subteam Meeting | B3: Network Team | C3: 45594 | D3: 0.041666667
A4: Initial Subteam Meeting | B4: Backend Team | C4: 45594 | D4: 0.041666667
A5: Initial Subteam Meeting | B5: Frontend Team | C5: 45594 | D5: 0.041666667
A6: SCRUM | B6: Network Team | C6: 45596 | D6: 0.041666667
A7: SCRUM | B7: Backend team | C7: 45596 | D7: 0.041666667
A8: SCRUM | B8: Lead Team | C8: 45598 | D8: 0.020833333
A9: SCRUM | B9: Frontend Team | C9: 45599 | D9: 0.041666667
A10: Compilation Meeting | B10: Lead Team | C10: 45599 | D10: 0.041666667
A11: P2 Planning | B11: Lead Team | C11: 45604 | D11: 0.041666667

Sheet Timeline
A1: Milestones | B1: Planned Start | C1: Planned Completed | D1: Actual Start | E1: Actual Completed
A2: Complete classes in the class structure diagram | B2: 45601 | C2: 45618
A3: Complete first game | B3: 45601 | C3: 45605
A4: Complete second game | B4: 45605 | C4: 45610
A5: Complete third game | B5: 45610 | C5: 45615
A6: Complete feedback for Delta and Echo team | B6: 45604 | C6: 45608
A7: Complete letter and submit P2 | B7: 45608 | C7: 45609
A8: Profile GUI | B8: 45602 | C8: 45618
A9: Complete networking stubs | B9: 45606 | C9: 45611
A10: Finalize leaderboard and matchmaking logic | B10: 45615 | C10: 45618
A11: Unit testing | B11: 45611 | C11: 45620
A12: Change classes according to P2 feedback | B12: 45614 | C12: 45618
A13: Integrate project from different teams | B13: 45619 | C13: 45621
... A17: Record group presentation video | B17: 45630 | C17: 45630

Sheet Setup
B2: Setup
B4: Category Name | C4: Employee Name
B5: Plan | C5: Rishabh Agarwal
B6: Design | C6: Sam Safe
B7: Code | C7: Victoria Piquer
B8: Document | C8: Tanisha Mattapalli
B9: Bugfix | C9: Sharon Wong
B10: Test | C10: Samuel Ergando
C11: Richard Nguyen
C12: Orest Sinani
C13: Nathan Phan
C14: Natesh Oad
C15: Mostafa Abdelazim
C16: Morteza Faraji
C17: Mohammad Moustaqim
C18: Michelle Yoon
C19: Lisa Tatarnikov
C20: Kyle Salazar
C21: Hassan Alvi
C22: Hannah Xia
... C29: Alan Bach
